Workbook

Sheet PETA-KAB_PROB

Sheet RA DATA
B1: ="DATA LEMBAGA MADRASAH RAODLATUL ATHFAL SEBANYAK "&B421 -> DATA LEMBAGA MADRASAH RAODLATUL ATHFAL SEBANYAK 419
B2: NO. | C2: NSM | D2: NPSN | E2: Nama Madrasah | F2: Jenjang | G2: Status | H2: Provinsi | I2: Kabupaten | J2: Kecamatan | K2: Alamat
B3: 1 | C3: 101235130004 | D3: 69745685 | E3: RA MIFTAHUL ULUM | F3: Raudhatul Athfal | G3: swasta | H3: JAWA TIMUR | I3: PROBOLINGGO | J3: BANTARAN | K3: JL. RAYA WONOASIH-BANTARAN KM03 RT. 01 RW. 02
B4: 2 | C4: 101235130005 | D4: 69745683 | E4: RA BUSTANUL ULUM | F4: Raudhatul Athfal | G4: swasta | H4: JAWA TIMUR | I4: PROBOLINGGO | J4: BANTARAN | K4: JL. TRIWUNG NO. 51 TEMPURAN
B5: 3 | C5: 101235130006 | D5: 69745684 | E5: RA DARUL ULUM BANTARAN | F5: Raudhatul Athfal | G5: swasta | H5: JAWA TIMUR | I5: PROBOLINGGO | J5: BANTARAN | K5: JLN RAYA 02 BANTARAN
B6: 4 | C6: 101235130007 | D6: 69745969 | E6: RA NURUL ULUM AL-ARIEF | F6: Raudhatul Athfal | G6: swasta | H6: JAWA TIMUR | I6: PROBOLINGGO | J6: BANTARAN | K6: DUSUN KRAJAN
B7: 5 | C7: 101235130008 | D7: 69887637 | E7: RA DARUL MA'ARIF | F7: Raudhatul Athfal | G7: swasta | H7: JAWA TIMUR | I7: PROBOLINGGO | J7: BANTARAN | K7: JALAN KRAMAT DESA KRAMATAGUNG
B8: 6 | C8: 101235130009 | D8: 69745682 | E8: RA NURUL HUDA | F8: Raudhatul Athfal | G8: swasta | H8: JAWA TIMUR | I8: PROBOLINGGO | J8: BANTARAN | K8: JL. KH. MAS SHOLEH MUDZAKKIR KRAMATAGUNG
B9: 7 | C9: 101235130010 | D9: 69745686 | E9: RA NURUL HIKMAH | F9: Raudhatul Athfal | G9: swasta | H9: JAWA TIMUR | I9: PROBOLINGGO | J9: BANTARAN | K9: JL.MASJID AZIZURROHIM DUSUN SUMUR RT007 RW 003
B10: 8 | C10: 101235130332 | D10: 69898093 | E10: RA NURUL YAQIN BANTARAN | F10: Raudhatul Athfal | G10: swasta | H10: JAWA TIMUR | I10: PROBOLINGGO | J10: BANTARAN | K10: JLN DUSUN PENGUMBIN RT021 RW006 KRAMATAGUNG
B11: 9 | C11: 101235130335 | D11: 69745681 | E11: RA MIFTAHUL HUDA | F11: Raudhatul Athfal | G11: swasta | H11: JAWA TIMUR | I11: PROBOLINGGO | J11: BANTARAN | K11: DUSUN TENGAH A
B12: 10 | C12: 101235130396 | D12: 69941128 | E12: RA NURUR ROHMAH | F12: Raudhatul Athfal | G12: swasta | H12: JAWA TIMUR | I12: PROBOLINGGO | J12: BANTARAN | K12: JL.KAPURAN RT.17/05
B13: 11 | C13: 101235130813 | D13: 70034839 | E13: RA UMMUL QURO AL JAUHARI | F13: Raudhatul Athfal | G13: swasta | H13: JAWA TIMUR | I13: PROBOLINGGO | J13: BANTARAN | K13: DUSUN TIMBANGAN RT 15 RW 03
B14: 12 | C14: 101235130818 | D14: 70036455 | E14: RA AL HIDAYAH | F14: Raudhatul Athfal | G14: swasta | H14: JAWA TIMUR | I14: PROBOLINGGO | J14: BANTARAN | K14: DSN. NANGKA
... B181: 179 | C181: 101235130092 | D181: 69958146 | E181: RA AL-ISLAM | F181: Raudhatul Athfal | G181: swasta | H181: JAWA TIMUR | I181: PROBOLINGGO | J181: KRUCIL | K181: DUSUN PESAPEN
B182: 180 | C182: 101235130093 | E182: RA HAYATUL ISLAM ROTO | F182: Raudhatul Athfal | G182: swasta | H182: JAWA TIMUR | I182: PROBOLINGGO | J182: KRUCIL | K182: Roto Krucil
B183: 181 | C183: 101235130094 | D183: 69745826 | E183: RA HIDAYATUL MUBTADIIN | F183: Raudhatul Athfal | G183: swasta | H183: JAWA TIMUR | I183: PROBOLINGGO | J183: KRUCIL | K183: DSN KALIMANGUK RT 08 RW 02
B184: 182 | C184: 101235130095 | D184: 69745833 | E184: RA ISLAMIYAH | F184: Raudhatul Athfal | G184: swasta | H184: JAWA TIMUR | I184: PROBOLINGGO | J184: KRUCIL | K184: DUSUN MANDATI RT. 013 RW. 004
B185: 183 | C185: 101235130096 | D185: 69745827 | E185: RA IZZUL ISLAM | F185: Raudhatul Athfal | G185: swasta | H185: JAWA TIMUR | I185: PROBOLINGGO | J185: KRUCIL | K185: DSN PESAPEN RT 07 RW 03
B186: 184 | C186: 101235130097 | D186: 69745829 | E186: RA AINUL IMAN | F186: Raudhatul Athfal | G186: swasta | H186: JAWA TIMUR | I186: PROBOLINGGO | J186: KRUCIL | K186: DUSUN RAWA RT. 02 RW. 03
B187: 185 | C187: 101235130098 | D187: 69745834 | E187: RA MAMBAUL ULUM | F187: Raudhatul Athfal | G187: swasta | H187: JAWA TIMUR | I187: PROBOLINGGO | J187: KRUCIL | K187: Dusun Manggisan
B188: 186 | C188: 101235130099 | D188: 69745835 | E188: RA MASYITHOH | F188: Raudhatul Athfal | G188: swasta | H188: JAWA TIMUR | I188: PROBOLINGGO | J188: KRUCIL | K188: DUSUN TENGAH RT 09 RW 02
B189: 187 | C189: 101235130099 | D189: 69745835 | E189: RA MASYITHOH | F189: Raudhatul Athfal | G189: swasta | H189: JAWA TIMUR | I189: PROBOLINGGO | J189: KRUCIL | K189: DUSUN TENGAH RT 09 RW 02
B190: 188 | C190: 101235130100 | D190: 69941131 | E190: RA MIFTAHUL HASAN | F190: Raudhatul Athfal | G190: swasta | H190: JAWA TIMUR | I190: PROBOLINGGO | J190: KRUCIL | K190: DUSUN KALITENGAH RT. 15 RW. 04 Desa Tambelang Kecamatan Krucil
B191: 189 | C191: 101235130101 | D191: 69898098 | E191: RA MIFTAHUL ISLAM KROBUNGAN | F191: Raudhatul Athfal | G191: swasta | H191: JAWA TIMUR | I191: PROBOLINGGO | J191: KRUCIL | K191: DUSUN KRAJAN RT.02 RW.01
B192: 190 | C192: 101235130102 | D192: 69958148 | E192: RA MIFTAHUL ULUM | F192: Raudhatul Athfal | G192: swasta | H192: JAWA TIMUR | I192: PROBOLINGGO | J192: KRUCIL | K192: SUMBERAN
B193: 191 | C193: 101235130103 | D193: 69898099 | E193: RA NURL ISLAM 2 WATUPANJANG | F193: Raudhatul Athfal | G193: swasta | H193: JAWA TIMUR | I193: PROBOLINGGO | J193: KRUCIL | K193: DUSUN KRAJAN RT. 002 RW. 001
B194: 192 | C194: 101235130104 | D194: 69898100 | E194: RA NURUL JADID | F194: Raudhatul Athfal | G194: swasta | H194: JAWA TIMUR | I194: PROBOLINGGO | J194: KRUCIL | K194: DEWI RENGGANIS RT,03. RW,01 KALIANAN KECAMATAN KRUCIL
... B209: 207 | C209: 101235130814 | D209: 70034663 | E209: RA KARAMATULLAH | F209: Raudhatul Athfal | G209: swasta | H209: JAWA TIMUR | I209: PROBOLINGGO | J209: KRUCIL | K209: BETEK KRUCIL PROBOLINGGO
B210: 208 | C210: 101235130826 | E210: RA SIROJUL KARIM | F210: Raudhatul Athfal | G210: swasta | H210: JAWA TIMUR | I210: PROBOLINGGO | J210: KRUCIL | K210: Bermi Utara RT 11 RW 03
B211: 209 | C211: 101235130001 | D211: 69745842 | E211: RA AR RAHMAN | F211: Raudhatul Athfal | G211: swasta | H211: JAWA TIMUR | I211: PROBOLINGGO | J211: KURIPAN | K211: Jl. Raya Kuripan Dusun Sumbersari RT 001 RW 003
B212: 210 | C212: 101235130002 | D212: 69898106 | E212: RA NURUL AFIFAH KURIPAN | F212: Raudhatul Athfal | G212: swasta | H212: JAWA TIMUR | I212: PROBOLINGGO | J212: KURIPAN | K212: JL. TRUNO REJO NO. 17
B213: 211 | C213: 101235130003 | D213: 69887643 | E213: RA MIFTAHUL ULUM JATISARI | F213: Raudhatul Athfal | G213: swasta | H213: JAWA TIMUR | I213: PROBOLINGGO | J213: KURIPAN | K213: Dusun Pering Rt 002 / Rw 002
B214: 212 | C214: 101235130336 | D214: 69745843 | E214: RA AL IDRISIYAH | F214: Raudhatul Athfal | G214: swasta | H214: JAWA TIMUR | I214: PROBOLINGGO | J214: KURIPAN | K214: WRINGINANOM
B215: 213 | C215: 101235130815 | D215: 70039883 | E215: RA MIFTAHUL ULUM | F215: Raudhatul Athfal | G215: swasta | H215: JAWA TIMUR | I215: PROBOLINGGO | J215: KURIPAN | K215: Jl. Kaligunde RT/RW 05/01
B216: 214 | C216: 101235130828 | E216: RA RADEN SAID SUNAN KALIJAGA | F216: Raudhatul Athfal | G216: swasta | H216: JAWA TIMUR | I216: PROBOLINGGO | J216: KURIPAN | K216: KEDUNG GLAGAH RT.02 RW.04
B217: 215 | C217: 101235130011 | D217: 69745852 | E217: RA NURUL HUDA | F217: Raudhatul Athfal | G217: swasta | H217: JAWA TIMUR | I217: PROBOLINGGO | J217: LECES | K217: DUSUN MASJID
B218: 216 | C218: 101235130012 | D218: 69745857 | E218: RA SULLAMUL HIDAYAH | F218: Raudhatul Athfal | G218: swasta | H218: JAWA TIMUR | I218: PROBOLINGGO | J218: LECES | K218: JL. KYAI MAKSUM
B219: 217 | C219: 101235130013 | D219: 69745855 | E219: RA ZAINUL IRSYAD | F219: Raudhatul Athfal | G219: swasta | H219: JAWA TIMUR | I219: PROBOLINGGO | J219: LECES | K219: JL. RAYA LUMAJANG NO. 50
B220: 218 | C220: 101235130014 | D220: 69745850 | E220: RA MISBAHUT THOLIBIN | F220: Raudhatul Athfal | G220: swasta | H220: JAWA TIMUR | I220: PROBOLINGGO | J220: LECES | K220: JORONGAN
...

Sheet MI DATA
A1: ="DATA LEMBAGA MADRASAH RAODLATUL ATHFAL SEBANYAK "&A417 -> DATA LEMBAGA MADRASAH RAODLATUL ATHFAL SEBANYAK 415
A2: No | B2: NSM | C2: NPSN | D2: Nama Madrasah | E2: Jenjang | F2: Status | G2: Provinsi | H2: Kabupaten | I2: Kecamatan | J2: Alamat
A3: 1 | B3: 111235130005 | C3: 60716271 | D3: MIS BUSTANUL ULUM | E3: Madrasah Ibtidaiyah | F3: swasta | G3: JAWA TIMUR | H3: PROBOLINGGO | I3: BANTARAN | J3: JL. TRIWUNG NO. 51 RT 11 RW 03 TEMPURAN
A4: 2 | B4: 111235130006 | C4: 60716272 | D4: MIS DARU MAFATIHIL ULUM | E4: Madrasah Ibtidaiyah | F4: swasta | G4: JAWA TIMUR | H4: PROBOLINGGO | I4: BANTARAN | J4: JL. PESANTREN NO. 659 RT/RW : 12/05
A5: 3 | B5: 111235130007 | C5: 60716273 | D5: MIS DARUL MAARIF | E5: Madrasah Ibtidaiyah | F5: swasta | G5: JAWA TIMUR | H5: PROBOLINGGO | I5: BANTARAN | J5: JLN. KRAMAT DESA KRAMATAGUNG
A6: 4 | B6: 111235130008 | C6: 60716274 | D6: MIS DARUL MUTAALLIMIN | E6: Madrasah Ibtidaiyah | F6: swasta | G6: JAWA TIMUR | H6: PROBOLINGGO | I6: BANTARAN | J6: DUSUN KRAJAN RT 002/ RW 001 DESA LEGUNDI BANTARAN PROBOLINGGO
A7: 5 | B7: 111235130009 | C7: 60716275 | D7: MIS DARUL ULUM KARANGANYAR | E7: Madrasah Ibtidaiyah | F7: swasta | G7: JAWA TIMUR | H7: PROBOLINGGO | I7: BANTARAN | J7: KARANGANYAR
A8: 6 | B8: 111235130010 | C8: 60716276 | D8: MIS DARUL ULUM BANTARAN | E8: Madrasah Ibtidaiyah | F8: swasta | G8: JAWA TIMUR | H8: PROBOLINGGO | I8: BANTARAN | J8: JLN RAYA 02 BANTARAN
A9: 7 | B9: 111235130011 | C9: 60716277 | D9: MIS INFARUL GHAY | E9: Madrasah Ibtidaiyah | F9: swasta | G9: JAWA TIMUR | H9: PROBOLINGGO | I9: BANTARAN | J9: DUSUN BATA
A10: 8 | B10: 111235130012 | C10: 60716278 | D10: MIS MIFTAHUL HUDA | E10: Madrasah Ibtidaiyah | F10: swasta | G10: JAWA TIMUR | H10: PROBOLINGGO | I10: BANTARAN | J10: DUSUN CANGAKAN RT 010 RW 004 DESA KEDUNGREJO
A11: 9 | B11: 111235130013 | C11: 60716279 | D11: MIS MIFTAHUL HUDA | E11: Madrasah Ibtidaiyah | F11: swasta | G11: JAWA TIMUR | H11: PROBOLINGGO | I11: BANTARAN | J11: DUSUN TENGAH A RT. 11 RW. 04 KRAMATAGUNG BANTARAN PROBOLINGGO
A12: 10 | B12: 111235130014 | C12: 60716280 | D12: MIS MIFTAHUL ULUM LEGUNDI | E12: Madrasah Ibtidaiyah | F12: swasta | G12: JAWA TIMUR | H12: PROBOLINGGO | I12: BANTARAN | J12: DESA LEGUNDI KEC. BANTARAN KAB. PROBOLINGGO
A13: 11 | B13: 111235130015 | C13: 60716281 | D13: MIS MIFTAHUL ULUM | E13: Madrasah Ibtidaiyah | F13: swasta | G13: JAWA TIMUR | H13: PROBOLINGGO | I13: BANTARAN | J13: JL. RAYA WONOASIH-BANTARAN KM 03 KROPAK
A14: 12 | B14: 111235130016 | C14: 60716282 | D14: MIS NURUL HUDA | E14: Madrasah Ibtidaiyah | F14: swasta | G14: JAWA TIMUR | H14: PROBOLINGGO | I14: BANTARAN | J14: JL. KH. MAS SHOLEH MUDZAKKIR KRAMATAGUNG
... A417: 415 | B417: 111235131003 | C417: 69977705 | D417: MIS RAUDLATUL HASAN | E417: Madrasah Ibtidaiyah | F417: swasta | G417: JAWA TIMUR | H417: PROBOLINGGO | I417: WONOMERTO | J417: Dusun Petung RT. 05 RW.03

Sheet MTs DATA
B1: ="DATA LEMBAGA MADRASAH TSANAWIYAH SEBANNYAK "&A224 -> DATA LEMBAGA MADRASAH TSANAWIYAH SEBANNYAK 222
A2: NO | B2: NSM | C2: NPSN | D2: Nama Madrasah | E2: Jenjang | F2: Status | G2: Provinsi | H2: Kabupaten | I2: Kecamatan | J2: Alamat
A3: 1 | B3: 121235130008 | C3: 20581885 | D3: MTSS UMMUL QURO | E3: Madrasah Tsanawiyah | F3: swasta | G3: JAWA TIMUR | H3: PROBOLINGGO | I3: BANTARAN | J3: JL. RAYA BANTARAN NO.39
A4: 2 | B4: 121235130010 | C4: 20581883 | D4: MTSS IRSYADUDDINIYAH | E4: Madrasah Tsanawiyah | F4: swasta | G4: JAWA TIMUR | H4: PROBOLINGGO | I4: BANTARAN | J4: JL. RAYA PATOKAN NO. 73 RT. 005/RW. 002
A5: 3 | B5: 121235130012 | C5: 20581884 | D5: MTSS DARU MAFATIHIL ULUM | E5: Madrasah Tsanawiyah | F5: swasta | G5: JAWA TIMUR | H5: PROBOLINGGO | I5: BANTARAN | J5: JL. PESANTREN NO. 659 RT/RW : 12/05
A6: 4 | B6: 121235130053 | C6: 20581886 | D6: MTSS MIFTAHUL HUDA | E6: Madrasah Tsanawiyah | F6: swasta | G6: JAWA TIMUR | H6: PROBOLINGGO | I6: BANTARAN | J6: Tengah A, RT/RW : 011/004 Kramatagung Bantaran Probolinggo
A7: 5 | B7: 121235130054 | C7: 20581887 | D7: MTSS DARUN NAJJAH | E7: Madrasah Tsanawiyah | F7: swasta | G7: JAWA TIMUR | H7: PROBOLINGGO | I7: BANTARAN | J7: JL. RAYA BANTARAN GG. PANDEAN JAYA RT 01 RW 01 DUSUN KRAJAN
A8: 6 | B8: 121235130076 | C8: 69726718 | D8: MTSS DARUL MUTA ALLIMIN | E8: Madrasah Tsanawiyah | F8: swasta | G8: JAWA TIMUR | H8: PROBOLINGGO | I8: BANTARAN | J8: Dsn Krajan RT 02/ RW 01
A9: 7 | B9: 121235130084 | C9: 20581882 | D9: MTSS MIFTAHUL ULUM | E9: Madrasah Tsanawiyah | F9: swasta | G9: JAWA TIMUR | H9: PROBOLINGGO | I9: BANTARAN | J9: Jl. Raya Wonoasih-Bantaran Km-03 Kropak Bantaran Probolinggo
A10: 8 | B10: 121235130085 | C10: 20581890 | D10: MTSS MIFTAHUL ULUM TEMPURAN | E10: Madrasah Tsanawiyah | F10: swasta | G10: JAWA TIMUR | H10: PROBOLINGGO | I10: BANTARAN | J10: Jl. kh. Anom Rt 013 Rw 004
A11: 9 | B11: 121235130159 | C11: 20581889 | D11: MTSS DARUL ULUM BANTARAN | E11: Madrasah Tsanawiyah | F11: swasta | G11: JAWA TIMUR | H11: PROBOLINGGO | I11: BANTARAN | J11: JL. RAYA 02 BANTARAN
A12: 10 | B12: 121235130171 | C12: 69853371 | D12: MTSS BUSTANUL ULUM | E12: Madrasah Tsanawiyah | F12: swasta | G12: JAWA TIMUR | H12: PROBOLINGGO | I12: BANTARAN | J12: JL. TRIWUNG NO. 51 RT. 011 / RW. 003
A13: 11 | B13: 121235130178 | C13: 69886413 | D13: MTSS DARUL MA'ARIF | E13: Madrasah Tsanawiyah | F13: swasta | G13: JAWA TIMUR | H13: PROBOLINGGO | I13: BANTARAN | J13: JALAN. KRAMAT RT/RW 028/007 DESA KRAMATAGUNG
A14: 12 | B14: 121235130787 | C14: 69975797 | D14: MTSS DARUL HIKMAH AL-ISLAMY | E14: Madrasah Tsanawiyah | F14: swasta | G14: JAWA TIMUR | H14: PROBOLINGGO | I14: BANTARAN | J14: JL. RAYA KROPAK DUSUN TIMBANGAN
... A80: 78 | B80: 121235130120 | C80: 20581942 | D80: MTSS MIFTAHUL AFKAR | E80: Madrasah Tsanawiyah | F80: swasta | G80: JAWA TIMUR | H80: PROBOLINGGO | I80: KRAKSAAN | J80: JL. WALISONGO
A81: 79 | B81: 121235130805 | D81: MTS INSAN AL KARIM | E81: Madrasah Tsanawiyah | F81: swasta | G81: JAWA TIMUR | H81: PROBOLINGGO | I81: KRAKSAAN | J81: Dusun Nangger Rt.02 Rw. 05
A82: 80 | B82: 121235130006 | C82: 20581934 | D82: MTSS NURUD DA WAH | E82: Madrasah Tsanawiyah | F82: swasta | G82: JAWA TIMUR | H82: PROBOLINGGO | I82: KREJENGAN | J82: DUSUN PENANGAN
A83: 81 | B83: 121235130007 | C83: 69727646 | D83: MTSS NURUL ISTIFADAH | E83: Madrasah Tsanawiyah | F83: swasta | G83: JAWA TIMUR | H83: PROBOLINGGO | I83: KREJENGAN | J83: GEBANGAN
A84: 82 | B84: 121235130011 | C84: 20581936 | D84: MTSS NURUL HIDAYAH | E84: Madrasah Tsanawiyah | F84: swasta | G84: JAWA TIMUR | H84: PROBOLINGGO | I84: KREJENGAN | J84: Dusun Krajan Rt 04 Rw 01
A85: 83 | B85: 121235130020 | C85: 20581937 | D85: MTSS AL ISLAMIYAH | E85: Madrasah Tsanawiyah | F85: swasta | G85: JAWA TIMUR | H85: PROBOLINGGO | I85: KREJENGAN | J85: JL. Pahlawan No. 04 Krejengan
A86: 84 | B86: 121235130021 | C86: 20581935 | D86: MTSS RAUDLATUL MUTAALLIMIN | E86: Madrasah Tsanawiyah | F86: swasta | G86: JAWA TIMUR | H86: PROBOLINGGO | I86: KREJENGAN | J86: DUSUN KRAJAN
A87: 85 | B87: 121235130077 | C87: 20581930 | D87: MTSS DARUT TAUHID | E87: Madrasah Tsanawiyah | F87: swasta | G87: JAWA TIMUR | H87: PROBOLINGGO | I87: KREJENGAN | J87: JL. KH HASAN SAIFURRIDZAL
A88: 86 | B88: 121235130103 | C88: 20581929 | D88: MTSS AL-MUTTAHIDAH | E88: Madrasah Tsanawiyah | F88: swasta | G88: JAWA TIMUR | H88: PROBOLINGGO | I88: KREJENGAN | J88: JL. KH. ROFII SENTONG
A89: 87 | B89: 121235130107 | C89: 20581931 | D89: MTSS SUNAN AMPEL KAMALKUNING | E89: Madrasah Tsanawiyah | F89: swasta | G89: JAWA TIMUR | H89: PROBOLINGGO | I89: KREJENGAN | J89: DUSUN KRAJAN
A90: 88 | B90: 121235130108 | C90: 20581938 | D90: MTSS FATHUL ARIFIN | E90: Madrasah Tsanawiyah | F90: swasta | G90: JAWA TIMUR | H90: PROBOLINGGO | I90: KREJENGAN | J90: Dusun Kuripan
A91: 89 | B91: 121235130111 | C91: 20581932 | D91: MTSS AL HUSNA | E91: Madrasah Tsanawiyah | F91: swasta | G91: JAWA TIMUR | H91: PROBOLINGGO | I91: KREJENGAN | J91: Jl. KH. Muh. Khozin Dawuhan
A92: 90 | B92: 121235130112 | C92: 20581933 | D92: MTSS SIRAJUL ULUM | E92: Madrasah Tsanawiyah | F92: swasta | G92: JAWA TIMUR | H92: PROBOLINGGO | I92: KREJENGAN | J92: DUSUN KRAJAN 2
A93: 91 | B93: 121235130807 | C93: 70039470 | D93: MTs KAROMATUL HASAN | E93: Madrasah Tsanawiyah | F93: swasta | G93: JAWA TIMUR | H93: PROBOLINGGO | I93: KREJENGAN | J93: Dsn. Krajan Sumberkatimoho
... A161: 159 | B161: 121235130189 | C161: 69928003 | D161: MTSS SYARIEF HIDAYATULLAH | E161: Madrasah Tsanawiyah | F161: swasta | G161: JAWA TIMUR | H161: PROBOLINGGO | I161: PAITON | J161: JL. RAYA PAITON NO. 89
A162: 160 | B162: 121235130804 | D162: MTS AL AZHAR AL SYARIF | E162: Madrasah Tsanawiyah | F162: swasta | G162: JAWA TIMUR | H162: PROBOLINGGO | I162: PAITON | J162: JL.PP. NURUL JADID 99 PAITON PROBOLINGGO
A163: 161 | B163: 121235130069 | C163: 69727648 | D163: MTSS RAUDLATUS SHOLEH | E163: Madrasah Tsanawiyah | F163: swasta | G163: JAWA TIMUR | H163: PROBOLINGGO | I163: PAKUNIRAN | J163: Pakuniran
A164: 162 | B164: 121235130073 | C164: 20582008 | D164: MTSS RIYADLUS SHALIHIN | E164: Madrasah Tsanawiyah | F164: swasta | G164: JAWA TIMUR | H164: PROBOLINGGO | I164: PAKUNIRAN | J164: DUSUN KRAJAN
A165: 163 | B165: 121235130144 | C165: 20582010 | D165: MTSS BAITUL MUTTAQIN | E165: Madrasah Tsanawiyah | F165: swasta | G165: JAWA TIMUR | H165: PROBOLINGGO | I165: PAKUNIRAN | J165: JL. PAKUNIRAN
A166: 164 | B166: 121235130145 | C166: 20582011 | D166: MTSS MIFTAHUL HASANAH | E166: Madrasah Tsanawiyah | F166: swasta | G166: JAWA TIMUR | H166: PROBOLINGGO | I166: PAKUNIRAN | J166: JL. RANON 02 / DUSUN KRAJAN RT. 001 RW. 001
A167: 165 | B167: 121235130147 | C167: 20582009 | D167: MTSS SUNAN AMPEL PAKUNIRAN | E167: Madrasah Tsanawiyah | F167: swasta | G167: JAWA TIMUR | H167: PROBOLINGGO | I167: PAKUNIRAN | J167: JL. KERTONEGORO PAKUNIRAN
A168: 166 | B168: 121235130181 | C168: 69788379 | D168: MTSS RAUDLATUL HIDAYAH | E168: Madrasah Tsanawiyah | F168: swasta | G168: JAWA TIMUR | H168: PROBOLINGGO | I168: PAKUNIRAN | J168: DUSUN PETONG
A169: 167 | B169: 121235130785 | C169: 69977768 | D169: MTSS IHYAUL ISLAM | E169: Madrasah Tsanawiyah | F169: swasta | G169: JAWA TIMUR | H169: PROBOLINGGO | I169: PAKUNIRAN | J169: DUSUN KRAJAN RT. 003/002 DESA ALAS PANDAN, KECAMATAN PAKUNIRAN
A170: 168 | B170: 121235130789 | C170: 69993652 | D170: MTSS DARUL IHSAN | E170: Madrasah Tsanawiyah | F170: swasta | G170: JAWA TIMUR | H170: PROBOLINGGO | I170: PAKUNIRAN | J170: Jl. Kertonegoro No. 01 Desa Kertonegoro Kec. Pakuniran Kab. Probolinggo
A171: 169 | B171: 121235130791 | C171: 70007467 | D171: MTSS AL-HASYIMI | E171: Madrasah Tsanawiyah | F171: swasta | G171: JAWA TIMUR | H171: PROBOLINGGO | I171: PAKUNIRAN | J171: JL. KALIDANDAN RT. 01 RW. 01
A172: 170 | B172: 121235130818 | C172: 70035523 | D172: MTs DARUL ULUM ALPANCORI | E172: Madrasah Tsanawiyah | F172: swasta | G172: JAWA TIMUR | H172: PROBOLINGGO | I172: PAKUNIRAN | J172: Jl Air Terjun RT/RW 009/004
...

Sheet MA DATA
A1: ="DATA LEMBAGA MADRASAH TSANAWIYAH SEBANNYAK "&A136 -> DATA LEMBAGA MADRASAH TSANAWIYAH SEBANNYAK 134
A2: NO | B2: NSM | C2: NPSN | D2: Nama Madrasah | E2: Jenjang | F2: Status | G2: Provinsi | H2: Kabupaten | I2: Kecamatan | J2: Alamat | K2: Status Konfirmasi | L2: Afiliasi Organisasi
A3: 1 | B3: 131235130001 | C3: 20584518 | D3: MAS UMMUL QURO | E3: Madrasah Aliyah | F3: swasta | G3: JAWA TIMUR | H3: PROBOLINGGO | I3: BANTARAN | J3: JL. RAYA BANTARAN NO. 39 | K3: Sudah Konfirmasi
A4: 2 | B4: 131235130070 | C4: 69894871 | D4: MAS MIFTAHUL ULUM AN-NUR | E4: Madrasah Aliyah | F4: swasta | G4: JAWA TIMUR | H4: PROBOLINGGO | I4: BANTARAN | J4: Jl. Raya Wonoasih-Bantaran Km 03. Kropak Bantaran Probolinggo | K4: Sudah Konfirmasi
A5: 3 | B5: 131235130077 | C5: 69941745 | D5: MAS MIFTAHUL ULUM | E5: Madrasah Aliyah | F5: swasta | G5: JAWA TIMUR | H5: PROBOLINGGO | I5: BANTARAN | J5: DUSUN LAMPEAN | K5: Belum Konfirmasi
A6: 4 | B6: 131235130096 | C6: 69975840 | D6: MAS AL-ARIFIN | E6: Madrasah Aliyah | F6: swasta | G6: JAWA TIMUR | H6: PROBOLINGGO | I6: BANTARAN | J6: Jl. Kedung Manggis Blok Jembatan RT 14 RW 04 | K6: Sudah Konfirmasi | L6: NU
A7: 5 | B7: 131235130105 | C7: 70006690 | D7: MAS PROGRESIF UMMUL QURO | E7: Madrasah Aliyah | F7: swasta | G7: JAWA TIMUR | H7: PROBOLINGGO | I7: BANTARAN | J7: DUSUN KRAJAN RT. 002 RW. 001 | K7: Sudah Konfirmasi
A8: 6 | B8: 131235130117 | C8: 70034356 | D8: MA DARU MAFATIHIL ULUM | E8: Madrasah Aliyah | F8: swasta | G8: JAWA TIMUR | H8: PROBOLINGGO | I8: BANTARAN | J8: JL. PESANTREN NO. 659 RT/RW : 012/005 | K8: Sudah Konfirmasi | L8: NU
A9: 7 | B9: 131235130131 | C9: 70034680 | D9: MA IRSYADUDDINIYAH | E9: Madrasah Aliyah | F9: swasta | G9: JAWA TIMUR | H9: PROBOLINGGO | I9: BANTARAN | J9: JL. RAYA PATOKAN NO. 73 RT/RW : 005/002 | K9: Sudah Konfirmasi | L9: NU
A10: 8 | B10: 131235130002 | C10: 20579871 | D10: MAS MIRQATUL ULUM | E10: Madrasah Aliyah | F10: swasta | G10: JAWA TIMUR | H10: PROBOLINGGO | I10: BANYUANYAR | J10: DUSUN NYABRANG | K10: Sudah Konfirmasi | L10: NU
A11: 9 | B11: 131235130003 | C11: 20579872 | D11: MAS MISBAHUL FATA | E11: Madrasah Aliyah | F11: swasta | G11: JAWA TIMUR | H11: PROBOLINGGO | I11: BANYUANYAR | J11: JL. SIHA NO. 45 DUSUN SUKUN RT. 02 RW. 02 | K11: Sudah Konfirmasi | L11: NU
A12: 10 | B12: 131235130004 | C12: 20584513 | D12: MAS SUNAN KALIJAGA | E12: Madrasah Aliyah | F12: swasta | G12: JAWA TIMUR | H12: PROBOLINGGO | I12: BANYUANYAR | J12: DUSUN SEKOLAHAN RT. 011 RW. 004 BANYUANYAR TENGAH | K12: Sudah Konfirmasi | L12: NU
A13: 11 | B13: 131235130060 | C13: 20579853 | D13: MAS IHYAUL ISLAM | E13: Madrasah Aliyah | F13: swasta | G13: JAWA TIMUR | H13: PROBOLINGGO | I13: BANYUANYAR | J13: KLENANG KIDUL | K13: Sudah Konfirmasi | L13: NU
A14: 12 | B14: 131235130062 | C14: 60728136 | D14: MAS NURIDDAHLANI | E14: Madrasah Aliyah | F14: swasta | G14: JAWA TIMUR | H14: PROBOLINGGO | I14: BANYUANYAR | J14: JL. JEMBATAN BARU HM DAHLAN | K14: Sudah Konfirmasi | L14: NU
A15: 13 | B15: 131235130098 | C15: 69993356 | D15: MAS WALISONGO 2 BANYUANYAR | E15: Madrasah Aliyah | F15: swasta | G15: JAWA TIMUR | H15: PROBOLINGGO | I15: BANYUANYAR | J15: JL. MASJID BESAR BANYUANYAR | K15: Sudah Konfirmasi | L15: NU
A16: 14 | B16: 131235130112 | C16: 70006687 | D16: MAS AL-KHOZINIYAH | E16: Madrasah Aliyah | F16: swasta | G16: JAWA TIMUR | H16: PROBOLINGGO | I16: BANYUANYAR | J16: DUSUN PAO RT 07 RT 02 | K16: Sudah Konfirmasi | L16: NU
A17: 15 | B17: 131235130136 | C17: 70044832 | D17: MA NURIL HISYAM | E17: Madrasah Aliyah | F17: swasta | G17: JAWA TIMUR | H17: PROBOLINGGO | I17: BANYUANYAR | J17: JALAN PENDIL KRAJAN RT.27 RW.07 | K17: Sudah Konfirmasi | L17: NU
A18: 16 | B18: 131235130005 | C18: 20579845 | D18: MAS BAHRUL ULUM | E18: Madrasah Aliyah | F18: swasta | G18: JAWA TIMUR | H18: PROBOLINGGO | I18: BESUK | J18: Jl. Raya Besuk No. 247 | K18: Sudah Konfirmasi
A19: 17 | B19: 131235130088 | C19: 69977841 | D19: MAS NURUL WAHID AL-WAHYUNI | E19: Madrasah Aliyah | F19: swasta | G19: JAWA TIMUR | H19: PROBOLINGGO | I19: BESUK | J19: JL. K. KATSIR DUSUN TALAR 02 | K19: Sudah Konfirmasi | L19: NU
A20: 18 | B20: 131235130133 | C20: 70045552 | D20: MA MIFTAHUL KHAIR | E20: Madrasah Aliyah | F20: swasta | G20: JAWA TIMUR | H20: PROBOLINGGO | I20: BESUK | J20: JALAN HABIB AHMAD | K20: Sudah Konfirmasi | L20: NU
A21: 19 | B21: 131235130006 | C21: 20584506 | D21: MAS AL-UM | E21: Madrasah Aliyah | F21: swasta | G21: JAWA TIMUR | H21: PROBOLINGGO | I21: DRINGU | J21: JL. SINTO RONGGOJALU KM. 1 | K21: Sudah Konfirmasi | L21: Lainnya
A22: 20 | B22: 131235130101 | C22: 70006686 | D22: MAS DARUS SALAM NGEPOH | E22: Madrasah Aliyah | F22: swasta | G22: JAWA TIMUR | H22: PROBOLINGGO | I22: DRINGU | J22: DUSUN MAKAM RT. 07 RW. 02 | K22: Sudah Konfirmasi | L22: NU
A23: 21 | B23: 131235130007 | C23: 20579869 | D23: MAS MIFTAHUL JANNAH | E23: Madrasah Aliyah | F23: swasta | G23: JAWA TIMUR | H23: PROBOLINGGO | I23: GADING | J23: JL. MAY JEND WIDODO 53 WANGKAL | K23: Sudah Konfirmasi | L23: NU
A24: 22 | B24: 131235130008 | C24: 20584524 | D24: MAS ZAINUL HASAN 2 | E24: Madrasah Aliyah | F24: swasta | G24: JAWA TIMUR | H24: PROBOLINGGO | I24: GADING | J24: JL. KH. MOH. HASAN NO. 99 | K24: Sudah Konfirmasi | L24: NU
A25: 23 | B25: 131235130069 | C25: 69894867 | D25: MAS DARUL HASAN | E25: Madrasah Aliyah | F25: swasta | G25: JAWA TIMUR | H25: PROBOLINGGO | I25: GADING | J25: JL. SEKARSARI DUSUN JANTI | K25: Sudah Konfirmasi | L25: NU
A26: 24 | B26: 131235130084 | C26: 69977837 | D26: MAS MIFTAHUL HASAN | E26: Madrasah Aliyah | F26: swasta | G26: JAWA TIMUR | H26: PROBOLINGGO | I26: GADING | J26: JL. R. SIDHARTA | K26: Sudah Konfirmasi
A27: 25 | B27: 131235130107 | C27: 70006685 | D27: MAS KHOLAFIYAH HASANIYAH | E27: Madrasah Aliyah | F27: swasta | G27: JAWA TIMUR | H27: PROBOLINGGO | I27: GADING | J27: JL. R. SIDHARTA NO. 45 RT. 05 RW. 03 Desa Gading Wetan | K27: Sudah Konfirmasi | L27: NU
A28: 26 | B28: 131235130114 | C28: 70034666 | D28: MA ROBITHATUL QUR'AN | E28: Madrasah Aliyah | F28: swasta | G28: JAWA TIMUR | H28: PROBOLINGGO | I28: GADING | J28: Dsn. Daris RT.001 RW.001 | K28: Sudah Konfirmasi
A29: 27 | B29: 131235130118 | C29: 70029187 | D29: MA Nurul Anwar | E29: Madrasah Aliyah | F29: swasta | G29: JAWA TIMUR | H29: PROBOLINGGO | I29: GADING | J29: Jl. Raya Sentul Dusun Krajan RT 001 RW 001 Desa Sentul Kecamatan Gading Kabupaten Probolinggo | K29: Sudah Konfirmasi
A30: 28 | B30: 131235130009 | C30: 20584520 | D30: MAS WALISONGO | E30: Madrasah Aliyah | F30: swasta | G30: JAWA TIMUR | H30: PROBOLINGGO | I30: GENDING | J30: Jl. Raya Sebaung Gending Probolinggo 67272 | K30: Sudah Konfirmasi | L30: NU
A31: 29 | B31: 131235130010 | C31: 20579870 | D31: MAS MIFTAHUL ULUM | E31: Madrasah Aliyah | F31: swasta | G31: JAWA TIMUR | H31: PROBOLINGGO | I31: GENDING | J31: Jl. Banyubiru Dsn. Krajan Banyuanyar Lor Gending Probolinggo | K31: Sudah Konfirmasi | L31: NU
A32: 30 | B32: 131235130071 | C32: 69886300 | D32: MAS FATAHILLAH | E32: Madrasah Aliyah | F32: swasta | G32: JAWA TIMUR | H32: PROBOLINGGO | I32: GENDING | J32: JL. PON.PES FATAHILLAH DUSUN TALANG RT. 03 RW. 05 DESA SUMBERKERANG | K32: Sudah Konfirmasi | L32: NU
A33: 31 | B33: 131235130099 | C33: 69994778 | D33: MAS TARBIYATUL ISLAM | E33: Madrasah Aliyah | F33: swasta | G33: JAWA TIMUR | H33: PROBOLINGGO | I33: GENDING | J33: DUSUN KARNIN WETAN NO. 254 SUMBERKERANG | K33: Sudah Konfirmasi
A34: 32 | B34: 131235130109 | C34: 70009431 | D34: MAS KETERAMPILAN NURUR ROHMAH | E34: Madrasah Aliyah | F34: swasta | G34: JAWA TIMUR | H34: PROBOLINGGO | I34: GENDING | J34: DUSUN DARUNGAN RT. 017 RW. 003 | K34: Sudah Konfirmasi | L34: Lainnya
A35: 33 | B35: 131235130124 | C35: 70041160 | D35: MA MODEL DARUSSALAM | E35: Madrasah Aliyah | F35: swasta | G35: JAWA TIMUR | H35: PROBOLINGGO | I35: GENDING | J35: KLASEMAN | K35: Sudah Konfirmasi | L35: NU
A36: 34 | B36: 131235130135 | C36: 70045243 | D36: MA UNGGULAN MASLAHATUL UMMAH | E36: Madrasah Aliyah | F36: swasta | G36: JAWA TIMUR | H36: PROBOLINGGO | I36: GENDING | J36: JALAN RAYA GENDING | K36: Sudah Konfirmasi | L36: NU
A37: 35 | B37: 131235130011 | C37: 20584514 | D37: MAS SYAFI'IYAH | E37: Madrasah Aliyah | F37: swasta | G37: JAWA TIMUR | H37: PROBOLINGGO | I37: KOTAANYAR | J37: JL. KH ZAINUL MUIN PP NURUR RAHMAH | K37: Sudah Konfirmasi | L37: NU
A38: 36 | B38: 131235130095 | C38: 69975839 | D38: MAS AL-KHOIRIYAH | E38: Madrasah Aliyah | F38: swasta | G38: JAWA TIMUR | H38: PROBOLINGGO | I38: KOTAANYAR | J38: JL. KOTAANYAR, BELAKANG SDN SIDOREJO | K38: Belum Konfirmasi | L38: NU
A39: 37 | B39: 131235130119 | C39: 70028215 | D39: MA TERPADU NURUL ANWAR | E39: Madrasah Aliyah | F39: swasta | G39: JAWA TIMUR | H39: PROBOLINGGO | I39: KOTAANYAR | J39: Dusun Krajan RT.10/Rw.05 | K39: Sudah Konfirmasi
A40: 38 | B40: 131235130126 | C40: 70043404 | D40: MA PROGRESIF BUMI AL-QUR'AN KOTAANYAR | E40: Madrasah Aliyah | F40: swasta | G40: JAWA TIMUR | H40: PROBOLINGGO | I40: KOTAANYAR | J40: Jl. Raya Gondosuli No.02 | K40: Belum Konfirmasi
...

Sheet Data Pengawas RA-MI
C2: =A62&" Pengawas RA/MI " -> 58 Pengawas RA/MI | E2: DATA PENGAWAS MADRASAH KANKEMENAG KAB. PROBOLINGGO JENJANG RA/MI
A4: No | B4: NIP | C4: NAMA | D4: L/P | E4: GOL | G4: TMT SP TERBARU | H4: JENJANG | I4: WILAYAH LAMA | J4: JENJANG SESUAI SK KEPENGAWAS AWAL | K4: TANGGAL LAHIR | L4: USIA | M4: DAMPAK ATURAN | N4: TANGGAL PANSIUN | O4: ALAMAT LENGKAP | P4: Kecamatan | Q4: NAMA
A5: 1 | B5: 196707202005011004 | C5: A. SULHAN, S.Ag | D5: L | E5: III/d | G5: 45474 | H5: RA/MI | I5: Pengawas RA,MI Kec. Paiton | J5: Pengawas RA/MI | K5: 24673 | L5: =DATEDIF(K5,TODAY(),"Y") -> 57 | M5: 58 | N5: =TEXT(EDATE(K5,12*M5),"DD MMMM YYYY") -> 20 Juli 2025 | O5: Jl. H. Mansur Tanjung lor RT. 25 RW. 12, Desa/Kel. Karanganyar, Kec. Paiton | P5: Paiton | Q5: A. SULHAN
A6: 2 | B6: 197007102000031005 | C6: ABD. HALIM, S.Pd.I | D6: L | E6: IV/b | G6: 44197 | H6: RA/MI | I6: Pengawas RA,MI Kec. Pakuniran | J6: Pengawas RA/MI | K6: 25759 | L6: =DATEDIF(K6,TODAY(),"Y") -> 54 | M6: 60 | N6: =TEXT(EDATE(K6,12*M6),"DD MMMM YYYY") -> 10 Juli 2030 | O6: Dusun Prasi Selatan RT. 17 RW. 07, Desa/Kel. Prasi, Kec. Gading | P6: Gading | Q6: ABD. HALIM
A7: 3 | B7: 197208162000031002 | C7: ABD. WAHID, S.Ag | D7: L | E7: IV/a | G7: Lama sekali | H7: RA/MI | I7: Pengawas RA, MI Kec. Tiris Barat | J7: Pengawas RA/MI | K7: 26527 | L7: =DATEDIF(K7,TODAY(),"Y") -> 52 | M7: 60 | N7: =TEXT(EDATE(K7,12*M7),"DD MMMM YYYY") -> 16 Agustus 2032 | O7: Dusun Krajan RT. 01 RW. 01, Desa/Kel. Sentul, Kec. Gading | P7: Gading | Q7: ABD. WAHID
A8: 4 | B8: 197303072005011004 | C8: ABDUL HAMID, S.Pd, M.Pd | D8: L | E8: IV/a | G8: 42430 | H8: RA/MI | I8: Pengawas RA,MI Kec. Krejengan | J8: Pengawas RA/MI | K8: 26730 | L8: =DATEDIF(K8,TODAY(),"Y") -> 51 | M8: 60 | N8: =TEXT(EDATE(K8,12*M8),"DD MMMM YYYY") -> 07 Maret 2033 | O8: Jl. Dimas Kanjeng No.135 RT. 20 RW. 08, Desa/Kel. Wangkal, Kec. Gading | P8: Gading | Q8: ABDUL HAMID
A9: 5 | B9: 197606182000031005 | C9: ABDUSSAMAT, S.Ag | D9: L | E9: III/c | G9: 45474 | H9: RA/MI | I9: Pengawas RA,MI Kec. Pakuniran | J9: Pengawas RA/MI | K9: 27929 | L9: =DATEDIF(K9,TODAY(),"Y") -> 48 | M9: 60 | N9: =TEXT(EDATE(K9,12*M9),"DD MMMM YYYY") -> 18 Juni 2036 | O9: Dusun Jukoan RT. 03 RW. 12, Desa/Kel. Kecik, Kec. Besuk | P9: Besuk | Q9: ABDUS SAMAT
A10: 6 | B10: 197808052005011004 | C10: AGUS SOLEH, S.Pd | D10: L | E10: III/d | G10: 45474 | H10: RA/MI | I10: Pengawas RA,MI Kec. Banyuanyar | J10: Pengawas RA/MI | K10: 28707 | L10: =DATEDIF(K10,TODAY(),"Y") -> 46 | M10: 60 | N10: =TEXT(EDATE(K10,12*M10),"DD MMMM YYYY") -> 05 Agustus 2038 | O10: Dusun Bengkingan RT. 01 RW. 01, Desa/Kel. Kalirejo, Kec. Dringu | P10: Dringu | Q10: AGUS SOLEH
A11: 7 | B11: 196712102005011002 | C11: AMIR MAHMUD, S.Pd,M.Pd.I | D11: L | E11: III/d | G11: 43556 | H11: RA/MI | I11: Pengawas RA,MI Kec. Kraksaan | J11: Pengawas RA/MI | K11: 24816 | L11: =DATEDIF(K11,TODAY(),"Y") -> 57 | M11: 58 | N11: =TEXT(EDATE(K11,12*M11),"DD MMMM YYYY") -> 10 Desember 2025 | O11: Dusun Tambak Rejo RT. 02 RW. 03, Desa/Kel. Kedungcaluk, Kec. Krejengan | P11: Krejengan | Q11: AMIR MAHMUD
A12: 8 | B12: 198304042005012004 | C12: ANGGRE AFREANDINA, S.Pd.SD | D12: P | E12: III/d | G12: 44868 | H12: RA/MI | I12: Pengawas RA,MI Kec. Krejengan | J12: Pengawas MI | K12: 30410 | L12: =DATEDIF(K12,TODAY(),"Y") -> 41 | M12: 60 | N12: =TEXT(EDATE(K12,12*M12),"DD MMMM YYYY") -> 04 April 2043 | O12: Jl PAHLAWAN RT. 02 RW. 01, Desa/Kel. Krejengan, Kec. Krejengan | P12: Krejengan | Q12: ANGGRE AFREANDINA
A13: 9 | B13: 197304152005012004 | C13: ASNITI, S.Pd | D13: P | E13: III/d | G13: 44868 | H13: RA/MI | I13: Pengawas RA,MI Kec. Leces | J13: Pengawas MI | K13: 26769 | L13: =DATEDIF(K13,TODAY(),"Y") -> 51 | M13: 60 | N13: =TEXT(EDATE(K13,12*M13),"DD MMMM YYYY") -> 15 April 2033 | O13: DUSUN KRAJAN 1 RT. 5 RW. 1, Desa/Kel. Clarak, Kec. Leces | P13: Leces | Q13: ASNITI
A14: 10 | B14: 196706102005011004 | C14: BAKRI , S.Pd | D14: L | E14: III/d | G14: 44470 | H14: RA/MI | I14: Pengawas RA,MI Kec. Paiton | J14: Pengawas RA/MI | K14: 24633 | L14: =DATEDIF(K14,TODAY(),"Y") -> 57 | M14: 58 | N14: =TEXT(EDATE(K14,12*M14),"DD MMMM YYYY") -> 10 Juni 2025 | O14: Dusun Krajan RT. 13 RW. 04, Desa/Kel. Kotaanyar, Kec. Kota Anyar | P14: Kotaanyar | Q14: BAKRI
A15: 11 | B15: 197705052005011008 | C15: DIAN EKO PRASETYONO, S.Pd | D15: L | E15: lll/d | G15: 45474 | H15: RA/MI | I15: Pengawas RA, MI Kec. Tiris Timur | J15: Pengawas MI | K15: 28250 | L15: =DATEDIF(K15,TODAY(),"Y") -> 47 | M15: 60 | N15: =TEXT(EDATE(K15,12*M15),"DD MMMM YYYY") -> 05 Mei 2037 | O15: Dusun Sukun RT. 02 RW. 01, Desa/Kel. Pendil, Kec. Banyu Anyar | P15: Banyuanyar | Q15: DIAN EKO PRASETYONO
A16: 12 | B16: 198212242005012003 | C16: DIANA DWI RAHAYU, S.Pd.SD,M.Pd | D16: P | E16: III/c | G16: 45474 | H16: RA/MI | I16: Pengawas RA,MI Kec. Gending | J16: Pengawas MI | K16: 30309 | L16: =DATEDIF(K16,TODAY(),"Y") -> 42 | M16: 60 | N16: =TEXT(EDATE(K16,12*M16),"DD MMMM YYYY") -> 24 Desember 2042 | O16: DUSUN GADING RT. 13 RW. 4, Desa/Kel. Wonorejo, Kec. Maron | P16: Maron | Q16: DIANA DWI RAHAYU
A17: 13 | B17: 198001022005011003 | C17: DIDIK IRAWAN, S.Pd | D17: L | E17: III/d | G17: 45474 | H17: RA/MI | I17: Pengawas RA,MI Kec. Maron | J17: Pengawas RA/MI | K17: 29222 | L17: =DATEDIF(K17,TODAY(),"Y") -> 45 | M17: 60 | N17: =TEXT(EDATE(K17,12*M17),"DD MMMM YYYY") -> 02 Januari 2040 | O17: Jl. DKA RT. 04 RW. 02, Desa/Kel. Brabe, Kec. Maron | P17: Maron | Q17: DIDIK IRAWAN
A18: 14 | B18: 196911232005012002 | C18: DIYAH TRI WAHTU UTAMI, S Pd | D18: P | E18: III/d | G18: 44823 | H18: RA/MI | I18: Pengawas RA,MI Kec. Krucil | J18: Pengawas RA/MI | K18: 25530 | L18: =DATEDIF(K18,TODAY(),"Y") -> 55 | M18: 60 | N18: =TEXT(EDATE(K18,12*M18),"DD MMMM YYYY") -> 23 November 2029 | O18: TAMBELANG TIMUR RT. 009 RW. 02, Desa/Kel. Krucil, Kec. Krucil | P18: Krucil | Q18: DIYAH TRI WAHTU UTAMI
A19: 15 | B19: 198101032005011003 | C19: DWI KARTIKO HADISAPUTRO, S.Pd | D19: L | E19: III/d | G19: 45108 | H19: RA/MI | I19: Pengawas RA,MI Kec. Krucil | J19: Pengawas MI | K19: 29589 | L19: =DATEDIF(K19,TODAY(),"Y") -> 44 | M19: 60 | N19: =TEXT(EDATE(K19,12*M19),"DD MMMM YYYY") -> 03 Januari 2041 | O19: Dusun Krajan 2 RT. 9 RW. 2, Desa/Kel. Maron Wetan, Kec. Maron | P19: Maron | Q19: DWI KARTIKO HADISAPUTRO
... A22: 18 | B22: 197609272005011002 | C22: HASAN, S.Pd.SD,M.Pd.I | D22: L | E22: III/d | G22: 45474 | H22: RA/MI | I22: Pengawas RA,MI Kec. Gading | J22: Pengawas RA/MI | K22: 28030 | L22: =DATEDIF(K22,TODAY(),"Y") -> 48 | M22: 60 | N22: =TEXT(EDATE(K22,12*M22),"DD MMMM YYYY") -> 27 September 2036 | O22: DUSUN KASENGAN RT. 04 RW. 02, Desa/Kel. Sumberkatimoho, Kec. Krejengan | P22: Krejengan | Q22: HASAN
A23: 19 | B23: 198306152005011006 | C23: HOSNAN, S.Pd.SD | D23: L | E23: III/d | G23: 01 Oktober 2021 | H23: RA/MI | I23: Pengawas RA,MI Kec. Kraksaan | J23: Pengawas RA/MI | K23: 30482 | L23: =DATEDIF(K23,TODAY(),"Y") -> 41 | M23: 60 | N23: =TEXT(EDATE(K23,12*M23),"DD MMMM YYYY") -> 15 Juni 2043 | O23: Pondok Pabean Indah Blok Kavling No KK 06 RT. 06 RW. 06, Desa/Kel. Pabean, Kec. Dringu | P23: Dringu | Q23: HOSNAN
A24: 20 | B24: 198301122005012002 | C24: IKA CANDRA DEWI, S.Pd | D24: P | E24: III/c | G24: 44868 | H24: RA/MI | I24: Pengawas RA, MI Kec. Tiris Timur | J24: Pengawas MI | K24: 30328 | L24: =DATEDIF(K24,TODAY(),"Y") -> 42 | M24: 60 | N24: =TEXT(EDATE(K24,12*M24),"DD MMMM YYYY") -> 12 Januari 2043 | O24: Dusun Krajan I RT. 17 RW. 06, Desa/Kel. Pesawahan, Kec. Tiris | P24: Tiris | Q24: IKA CANDRA DEWI
A25: 21 | B25: 197607052005011004 | C25: IMAM GHOZALI, S.Pd | D25: L | E25: lll/d | G25: 45078 | H25: RA/MI | I25: Pengawas RA, MI Kec. Tiris Barat | J25: Pengawas MI | K25: 27946 | L25: =DATEDIF(K25,TODAY(),"Y") -> 48 | M25: 60 | N25: =TEXT(EDATE(K25,12*M25),"DD MMMM YYYY") -> 05 Juli 2036 | O25: Dusun Gapur RT. 09 RW. 03, Desa/Kel. Brumbungan Lor, Kec. Gending | P25: Gending | Q25: IMAM GHOZALI
A26: 22 | B26: 197806242005011002 | C26: ISHAK, S.Pd | D26: L | E26: III/d | G26: 45474 | H26: RA/MI | I26: Pengawas RA, MI Kec. Tiris Timur | J26: Pengawas MI | K26: 28665 | L26: =DATEDIF(K26,TODAY(),"Y") -> 46 | M26: 60 | N26: =TEXT(EDATE(K26,12*M26),"DD MMMM YYYY") -> 24 Juni 2038 | O26: Dusun Krajan RT. 01 RW. 02, Desa/Kel. Bulujaran Kidul, Kec. Tegal Siwalan | P26: Tegalsiwalan | Q26: ISHAK
A27: 23 | B27: 198404112005011002 | C27: ISWANTO, S.Pd, M.Pd | D27: L | E27: III/d | G27: 45078 | H27: RA/MI | I27: Pengawas RA,MI Kec. Wonomerto, Tongas | J27: Pengawas MI | K27: 30783 | L27: =DATEDIF(K27,TODAY(),"Y") -> 40 | M27: 60 | N27: =TEXT(EDATE(K27,12*M27),"DD MMMM YYYY") -> 11 April 2044 | O27: DUSUN ASEM LURUS RT. 19 RW. 05, Desa/Kel. Muneng, Kec. Sumber Asih | P27: Sumberasih | Q27: ISWANTO
A28: 24 | B28: 196904282005012012 | C28: JUHAIRIYAH, S.Ag | D28: P | E28: IV/a | G28: 45474 | H28: RA/MI | I28: Pengawas RA,MI Kec. Banyuanyar | J28: Pengawas RA | K28: 25321 | L28: =DATEDIF(K28,TODAY(),"Y") -> 55 | M28: 60 | N28: =TEXT(EDATE(K28,12*M28),"DD MMMM YYYY") -> 28 April 2029 | O28: Dusun Kramat RT. 03 RW. 02, Desa/Kel. Puspan, Kec. Maron | P28: Maron | Q28: JUHAIRIYAH
A29: 25 | B29: 198207152005011002 | C29: KARIMUL HUDA, S.Pd | D29: L | E29: III/c | G29: 45078 | H29: RA/MI | I29: Pengawas RA,MI Kec. Bantaran | J29: Pengawas RA/MI | K29: 30147 | L29: =DATEDIF(K29,TODAY(),"Y") -> 42 | M29: 60 | N29: =TEXT(EDATE(K29,12*M29),"DD MMMM YYYY") -> 15 Juli 2042 | O29: Dusun Krasak RT. 09 RW. 02, Desa/Kel. Menyono, Kec. Kuripan | P29: Kuripan | Q29: KARIMUL HUDA
A30: 26 | B30: 197206302005011002 | C30: KHOLID MUSTOFA, S.Pd.I,M.Pd | D30: L | E30: III/d | G30: 45474 | H30: RA/MI | I30: Pengawas RA,MI Kec. Banyuanyar | J30: Pengawas RA/MI | K30: 26480 | L30: =DATEDIF(K30,TODAY(),"Y") -> 52 | M30: 60 | N30: =TEXT(EDATE(K30,12*M30),"DD MMMM YYYY") -> 30 Juni 2032 | O30: Dusun Paleran RT. 11 RW. 03, Desa/Kel. Maron Wetan, Kec. Maron | P30: Maron | Q30: KHOLID MUSTOFA
A31: 27 | B31: 196805071997031003 | C31: LUKMANUL HAKIM, M.Pd | D31: L | E31: IV/a | G31: 45474 | H31: RA/MI | I31: Pengawas RA,MI Kec. Maron | J31: Pengawas MI | K31: 24965 | L31: =DATEDIF(K31,TODAY(),"Y") -> 56 | M31: 60 | N31: =TEXT(EDATE(K31,12*M31),"DD MMMM YYYY") -> 07 Mei 2028 | O31: Jl. Sunan Kudus No.42 RT. 02 RW. 07, Desa/Kel. Kraksaan Wetan, Kec. Kraksaan | P31: Kraksaan | Q31: LUKMANUL HAKIM
A32: 28 | B32: 197107172005011006 | C32: M. MUSHLIH, S.Pd.I | D32: L | E32: IV/a | G32: 44652 | H32: RA/MI | I32: Pengawas RA,MI Kec. Lumbang, Sukapura | J32: Pengawas RA/MI | K32: 26131 | L32: =DATEDIF(K32,TODAY(),"Y") -> 53 | M32: 60 | N32: =TEXT(EDATE(K32,12*M32),"DD MMMM YYYY") -> 17 Juli 2031 | O32: Jln. Kyai wangi Dusun Bindung RT. 01 RW. 03, Desa/Kel. Tunggak Cerme, Kec. Wonomerto | P32: Wonomerto | Q32: M. MUSHLIH
A33: 29 | B33: 196904082005011002 | C33: MANSUR, S.PdI, M.Pd | D33: L | E33: III/d | G33: 45474 | H33: RA/MI | I33: Pengawas RA,MI Kec. Pajarakan | J33: Pengawas MI | K33: 25301 | L33: =DATEDIF(K33,TODAY(),"Y") -> 55 | M33: 58 | N33: =TEXT(EDATE(K33,12*M33),"DD MMMM YYYY") -> 08 April 2027 | O33: Dusun Skanan RT. 03 RW. 02, Desa/Kel. Rondokuning, Kec. Kraksaan | P33: Kraksaan | Q33: MANSUR
A34: 30 | B34: 197302041995032001 | C34: MARIA ULFAH, S.Pd.I | D34: P | E34: IV/c | G34: 44193 | H34: RA/MI | I34: Penagawas RA,MI Kec. Sumberasih | J34: Pengawas RA/MI | K34: 26699 | L34: =DATEDIF(K34,TODAY(),"Y") -> 51 | M34: 60 | N34: =TEXT(EDATE(K34,12*M34),"DD MMMM YYYY") -> 04 Februari 2033 | O34: JL. RAWA TIRTA RT. 01 RW. 08, Desa/Kel. Sumberkedawung, Kec. Leces | P34: Leces | Q34: MARIA ULFAH
A35: 31 | B35: 196709071993031003 | C35: Drs. MOH. WAHID ILHAM | D35: L | E35: IV/a | G35: 45474 | H35: RA/MI | I35: Pengawas RA,MI Kec. Bantaran | J35: Pengawas RA/MI | K35: 24722 | L35: =DATEDIF(K35,TODAY(),"Y") -> 57 | M35: 60 | N35: =TEXT(EDATE(K35,12*M35),"DD MMMM YYYY") -> 07 September 2027 | O35: Jl.Indragiri Gg.1 RT. 01 RW. 04, Desa/Kel. Jrebeng Wetan, Kec. Kedopok | P35: Kedopok | Q35: MOH. WAHID ILHAM
... A62: 58 | B62: 197811172005011002 | C62: Drs. ZAINUL HASAN, M.Pd.I | D62: P | E62: IV/a | G62: 44986 | H62: RA/MI | I62: Pengawas RA,MI Kec. Pakuniran | J62: Pengawas MI | K62: 28811 | L62: =DATEDIF(K62,TODAY(),"Y") -> 46 | M62: 60 | N62: =TEXT(EDATE(K62,12*M62),"DD MMMM YYYY") -> 17 November 2038 | O62: KARANGANOM RT. 09 RW. 05, Desa/Kel. Karanganyar, Kec. Paiton | P62: Paiton | Q62: ZAINUL HASAN
Q63: x

Sheet Data Pengawas MTS-MA
C2: =A24&" Pengawas MTs/MA " -> 20 Pengawas MTs/MA | F2: DATA PENGAWAS MADRASAH KANKEMENAG KAB. PROBOLINGGO JENJANG MTS / MA
A4: No | B4: NIP | C4: NAMA | D4: L/P | E4: GOL | F4: TMT SP TERBARU | G4: JENJANG | H4: WILAYAH LAMA | I4: JENJANG SESUAI SK KEPENGAWAS AWAL | J4: TANGGAL LAHIR | K4: USIA | L4: DAMPAK ATURAN | M4: TANGGAL PANSIUN | N4: ALAMAT LENGKAP | O4: Kecamatan | P4: NAMA
A5: 1 | B5: 197503232005011005 | C5: ABD. GHANI, S.Ag | D5: L | E5: III/d | F5: 45469 | G5: MTs | H5: Pengawas MTs Kec. Besuk, Krejengan | I5: Pengawas MTs | J5: 27476 | K5: =DATEDIF(J5,TODAY(),"Y") -> 49 | L5: 60 | M5: =TEXT(EDATE(J5,12*L5),"DD MMMM YYYY") -> 23 Maret 2035 | N5: SUMBERAN BESUK RT. 07 RW. 03, Desa/Kel. Sumberan, Kec. Besuk | O5: Besuk | P5: ABD. GHANI
A6: 2 | B6: 196705022002121001 | C6: ABDUL AZIS, S.Ag, M.Pd | D6: L | E6: IV/b | F6: 45124 | G6: MTs | H6: Pengawas MTs Kec. Paiton | I6: Pengawas MI | J6: 24594 | K6: =DATEDIF(J6,TODAY(),"Y") -> 57 | L6: 60 | M6: =TEXT(EDATE(J6,12*L6),"DD MMMM YYYY") -> 02 Mei 2027 | N6: Dusun I Krajan RT. 04 RW. 10, Desa/Kel. Sambirampak Kidul, Kec. Kota Anyar | O6: Kotaanyar | P6: ABDUL AZIS
A7: 3 | B7: 198110132009012006 | C7: DWI HALIMA TUTRIYANTI, S.Pd | D7: P | E7: III/d | F7: 44868 | G7: MTs | H7: Pengawas MTs,MA Kec. Bantaran | I7: Pengawas MTs | J7: 29872 | K7: =DATEDIF(J7,TODAY(),"Y") -> 43 | L7: 60 | M7: =TEXT(EDATE(J7,12*L7),"DD MMMM YYYY") -> 13 Oktober 2041 | N7: Jl. BANTARAN GG. DAHLIA RT. 09 RW. 10, Desa/Kel. Sumberkedawung, Kec. Leces | O7: Leces | P7: DWI HALIMA TUTRIYANTI
A8: 4 | B8: 196906092005011001 | C8: HARIANTO, S.Pd | D8: L | E8: III/d | F8: 43174 | G8: MTs | H8: Pengawas MTs Kec. Kotaanyar, Pakuniran, Krucil | I8: Pengawas MTs | J8: 25363 | K8: =DATEDIF(J8,TODAY(),"Y") -> 55 | L8: 60 | M8: =TEXT(EDATE(J8,12*L8),"DD MMMM YYYY") -> 09 Juni 2029 | N8: DUSUN KRAJAN RT. 12 RW. 06, Desa/Kel. Triwungan, Kec. Kota Anyar | O8: Kotaanyar | P8: HARIANTO
A9: 5 | B9: 197602162005011005 | C9: HERU KISWANTO, S.Pd | D9: L | E9: III/d | F9: 45474 | G9: MTs/MA | H9: Pengawas MTs, MA Kec. Tiris | I9: Pengawas MTs | J9: 27806 | K9: =DATEDIF(J9,TODAY(),"Y") -> 48 | L9: 60 | M9: =TEXT(EDATE(J9,12*L9),"DD MMMM YYYY") -> 16 Februari 2036 | N9: GANG KRAMAT RT. 06 RW. 02, Desa/Kel. Condong, Kec. Gading | O9: Gading | P9: HERU KISWANTO
A10: 6 | B10: 198208182005011004 | C10: HUSNAN ABRORI, S.Pd | D10: L | E10: III/d | F10: 45124 | G10: MTS/MA | H10: Pengawas MA Kec. Kotaanyar, Pakuniran, Paiton | I10: Pengawas MTs | J10: 30181 | K10: =DATEDIF(J10,TODAY(),"Y") -> 42 | L10: 60 | M10: =TEXT(EDATE(J10,12*L10),"DD MMMM YYYY") -> 18 Agustus 2042 | N10: DUSUN KRAJAN RT. 012 RW. 04, Desa/Kel. Sidomulyo, Kec. Kota Anyar | O10: Kotaanyar | P10: HUSNAN ABRORI
A11: 7 | B11: 197604222003122003 | C11: ISMAWATI, S.Pd,M.Pd | D11: P | E11: IV/a | F11: 45071 | G11: MTs/MA | H11: Pengawas MTs,MA Kec. Leces, Dringu | I11: Pengawas MTs | J11: 27872 | K11: =DATEDIF(J11,TODAY(),"Y") -> 48 | L11: 60 | M11: =TEXT(EDATE(J11,12*L11),"DD MMMM YYYY") -> 22 April 2036 | N11: Jl. Taman Bougenvil II No 7 RT. 06 RW. 07, Desa/Kel. Sumbertaman, Kec. Wonoasih | O11: Wonoasih | P11: ISMAWATI
A12: 8 | B12: 196604082000031001 | C12: MUSYAFI', S.Ag, SH, M.Pd | D12: L | E12: IV/b | F12: 40603 | G12: MA | H12: Pengawas MA Kec. Bantaran,Tegalsiwalan,Wonomerto | I12: Pengawas MTs/MA | J12: 24205 | K12: =DATEDIF(J12,TODAY(),"Y") -> 58 | L12: 60 | M12: =TEXT(EDATE(J12,12*L12),"DD MMMM YYYY") -> 08 April 2026 | N12: Dusun Grintingan RT. 019 RW. 03, Desa/Kel. Blado Kulon, Kec. Tegal Siwalan | O12: Tegalsiwalan | P12: MUSYAFI'
A13: 9 | B13: 197803172005012002 | C13: NETY MERY YASMIN, S.Pd,M.Pd | D13: P | E13: IV/a | F13: 45071 | G13: MTs/MA | H13: Pengawas MTs,MA Kec. Krejengan | I13: Pengawas MTs | J13: 28566 | K13: =DATEDIF(J13,TODAY(),"Y") -> 46 | L13: 60 | M13: =TEXT(EDATE(J13,12*L13),"DD MMMM YYYY") -> 17 Maret 2038 | N13: Jl. DR. SALEH RT. 1 RW. 3, Desa/Kel. Sumberlele, Kec. Kraksaan | O13: Kraksaan | P13: NETY MERY YASMIN
A14: 10 | B14: 196906262005012001 | C14: Dra. NUR SYAMSIAH ROHWENI | D14: P | E14: IV/b | F14: 44986 | G14: MTs | H14: Pengawas MTs, MA Kec. Tegalsiwalan, Banyuanyar | I14: Pengawas MTs | J14: 25380 | K14: =DATEDIF(J14,TODAY(),"Y") -> 55 | L14: 60 | M14: =TEXT(EDATE(J14,12*L14),"DD MMMM YYYY") -> 26 Juni 2029 | N14: Perum Melati Indah No 21 RT. 9 RW. 1, Desa/Kel. Sumberkedawung, Kec. Leces | O14: Leces | P14: NUR SYAMSIAH ROHWENI
A15: 11 | B15: 197105062005012004 | C15: NURHOIRIYAH, M.Pd.I | D15: P | E15: IV/b | F15: 45078 | G15: MTs/MA | H15: Pengawas MTs,MA Kec. Wonomerto, Bantaran | I15: Pengawas MTs/MA | J15: 26059 | K15: =DATEDIF(J15,TODAY(),"Y") -> 53 | L15: 60 | M15: =TEXT(EDATE(J15,12*L15),"DD MMMM YYYY") -> 06 Mei 2031 | N15: Dusun Asem Lurus RT. 005 RW. 20, Desa/Kel. Muneng, Kec. Sumber Asih | O15: Sumberasih | P15: NURHOIRIYAH
A16: 12 | B16: 197808042005011002 | C16: R. ACH. CHOIRUL FATAH, S.Pd | D16: L | E16: III/d | F16: 44470 | G16: MTs/MA | H16: Pengawas MTs,MA Kec. Gending,Sumberasih, Tongas, Kuripan, Lumbang | I16: Pengawas MTs | J16: 28706 | K16: =DATEDIF(J16,TODAY(),"Y") -> 46 | L16: 60 | M16: =TEXT(EDATE(J16,12*L16),"DD MMMM YYYY") -> 04 Agustus 2038 | N16: Jl. KH Hasan Bisri gang 1 No. 11 RT. 07 RW. 01, Desa/Kel. Sumbertaman, Kec. Wonoasih | O16: Wonoasih | P16: R. ACH. CHOIRUL FATAH
... A24: 20 | B24: 197309042005011001 | C24: SUPARMAN , S.Pd.I,M.Pd.I | D24: L | E24: III/d | F24: 45124 | G24: MTs | H24: Pengawas MTs,MA Kec. Tongas,Lumbang,Sumberasih | I24: Pengawas MTs | J24: 26911 | K24: =DATEDIF(J24,TODAY(),"Y") -> 51 | L24: 60 | M24: =TEXT(EDATE(J24,12*L24),"DD MMMM YYYY") -> 04 September 2033 | N24: JL TENGGER DUSUN PACAR RT. 07 RW. 02, Desa/Kel. Jangur, Kec. Sumber Asih | O24: Sumberasih | P24: SUPARMAN
P25: X

Sheet PETA-PENGAWAS
B1: TOTAL LEMBAGA | C1: JUMLAH PENGAWAS | H1: Memiliki jumlah minimal binaan sesuai ketentuan (salah satu harus memenuhi) Sebagaimana dalam Simpatika/Emis 4.0 | L1: JUMLAH PENGAWAS
B2: RA/MI/MTS/MA | C2: RA | G2: =COUNTIF('Data Pengawas Madrasah'!$G$5:$G$82,'PETA-PENGAWAS'!C2) -> 0 | H2: Bagi Pengawas RA/MI : | J2: 10 satuan pendidikan RA/MI | L2: MTs | O2: =COUNTIF('Data Pengawas Madrasah'!$G$5:$G$82,'PETA-PENGAWAS'!L2) -> 9 | P2: =SUM(O2:O4) -> 20
B3: =SUM(C34,E34,L34,N34) -> 1189 | C3: MI | G3: =COUNTIF('Data Pengawas Madrasah'!$G$5:$G$82,'PETA-PENGAWAS'!C3) -> 0 | J3: dan atau 60 guru RA/MI | L3: MTs/MA | O3: =COUNTIF('Data Pengawas Madrasah'!$G$5:$G$82,'PETA-PENGAWAS'!L3) -> 7
C4: RA/MI | G4: =COUNTIF('Data Pengawas Madrasah'!$G$5:$G$82,'PETA-PENGAWAS'!C4) -> 58 | H4: Bagi Pengawas MTs/MA : | J4: 7 satuan pendidikan MTs/MA/MAK | L4: MA | O4: =COUNTIF('Data Pengawas Madrasah'!$G$5:$G$82,'PETA-PENGAWAS'!L4) -> 4
J5: dan atau 40 guru MTs/MA/MAK
B6: KECAMATAN/KKM | C6: JUMLAH | H6: QUATA | I6: TAMBAHAN | K6: KECAMATAN | L6: JUMLAH | P6: QUATA | Q6: TAMBAHAN
C7: RA | D7: QUATA PENGAWAS | E7: MI | F7: QUATA PENGAWAS | G7: RA/MI | H7: PENGAWAS | I7: LEMBAGA | L7: MTs | M7: QUATA PENGAWAS | N7: MA | O7: MTs/MA | P7: PENGAWAS | Q7: LEMBAGA
B8: SUMBER | C8: =COUNTIF('RA DATA'!$J$3:$J$421,'PETA-PENGAWAS'!B8) -> 1 | E8: =COUNTIF('MI DATA'!$I$3:$I$417,'PETA-PENGAWAS'!B8) -> 0 | G8: =SUM(C8,E8) -> 1 | H8: 1 | K8: SUMBER | L8: =COUNTIF('MTs DATA'!$I$3:$I$224,'PETA-PENGAWAS'!K8) -> 0 | N8: =COUNTIF('MA DATA'!$I$3:$I$136,'PETA-PENGAWAS'!K8) -> 0 | O8: =SUM(L8:N8) -> 0 | P8: 1
B9: SUKAPURA | C9: =COUNTIF('RA DATA'!$J$3:$J$421,'PETA-PENGAWAS'!B9) -> 2 | E9: =COUNTIF('MI DATA'!$I$3:$I$417,'PETA-PENGAWAS'!B9) -> 0 | G9: =SUM(C9,E9) -> 2 | K9: SUKAPURA | L9: =COUNTIF('MTs DATA'!$I$3:$I$224,'PETA-PENGAWAS'!K9) -> 0 | N9: =COUNTIF('MA DATA'!$I$3:$I$136,'PETA-PENGAWAS'!K9) -> 0 | O9: =SUM(L9:N9) -> 0
B10: LUMBANG | C10: =COUNTIF('RA DATA'!$J$3:$J$421,'PETA-PENGAWAS'!B10) -> 7 | E10: =COUNTIF('MI DATA'!$I$3:$I$417,'PETA-PENGAWAS'!B10) -> 6 | G10: =SUM(C10,E10) -> 13 | K10: LUMBANG | L10: =COUNTIF('MTs DATA'!$I$3:$I$224,'PETA-PENGAWAS'!K10) -> 4 | N10: =COUNTIF('MA DATA'!$I$3:$I$136,'PETA-PENGAWAS'!K10) -> 3 | O10: =SUM(L10:N10) -> 7
B11: TONGAS | C11: =COUNTIF('RA DATA'!$J$3:$J$421,'PETA-PENGAWAS'!B11) -> 22 | E11: =COUNTIF('MI DATA'!$I$3:$I$417,'PETA-PENGAWAS'!B11) -> 12 | G11: =SUM(C11,E11) -> 34 | H11: 2 | K11: TONGAS | L11: =COUNTIF('MTs DATA'!$I$3:$I$224,'PETA-PENGAWAS'!K11) -> 4 | N11: =COUNTIF('MA DATA'!$I$3:$I$136,'PETA-PENGAWAS'!K11) -> 2 | O11: =SUM(L11:N11) -> 6
B12: WONOMERTO | C12: =COUNTIF('RA DATA'!$J$3:$J$421,'PETA-PENGAWAS'!B12) -> 7 | E12: =COUNTIF('MI DATA'!$I$3:$I$417,'PETA-PENGAWAS'!B12) -> 11 | G12: =SUM(C12,E12) -> 18 | H12: 1 | K12: WONOMERTO | L12: =COUNTIF('MTs DATA'!$I$3:$I$224,'PETA-PENGAWAS'!K12) -> 6 | N12: =COUNTIF('MA DATA'!$I$3:$I$136,'PETA-PENGAWAS'!K12) -> 2 | O12: =SUM(L12:N12) -> 8 | P12: 1
B13: KURIPAN | C13: =COUNTIF('RA DATA'!$J$3:$J$421,'PETA-PENGAWAS'!B13) -> 6 | E13: =COUNTIF('MI DATA'!$I$3:$I$417,'PETA-PENGAWAS'!B13) -> 9 | G13: =SUM(C13,E13) -> 15 | H13: 1 | K13: KURIPAN | L13: =COUNTIF('MTs DATA'!$I$3:$I$224,'PETA-PENGAWAS'!K13) -> 4 | N13: =COUNTIF('MA DATA'!$I$3:$I$136,'PETA-PENGAWAS'!K13) -> 1 | O13: =SUM(L13:N13) -> 5
B14: BANTARAN | C14: =COUNTIF('RA DATA'!$J$3:$J$421,'PETA-PENGAWAS'!B14) -> 13 | E14: =COUNTIF('MI DATA'!$I$3:$I$417,'PETA-PENGAWAS'!B14) -> 18 | G14: =SUM(C14,E14) -> 31 | H14: 2 | K14: BANTARAN | L14: =COUNTIF('MTs DATA'!$I$3:$I$224,'PETA-PENGAWAS'!K14) -> 13 | N14: =COUNTIF('MA DATA'!$I$3:$I$136,'PETA-PENGAWAS'!K14) -> 7 | O14: =SUM(L14:N14) -> 20 | P14: 1
B15: SUMBERASIH | C15: =COUNTIF('RA DATA'!$J$3:$J$421,'PETA-PENGAWAS'!B15) -> 16 | E15: =COUNTIF('MI DATA'!$I$3:$I$417,'PETA-PENGAWAS'!B15) -> 8 | G15: =SUM(C15,E15) -> 24 | H15: 1 | K15: SUMBERASIH | L15: =COUNTIF('MTs DATA'!$I$3:$I$224,'PETA-PENGAWAS'!K15) -> 8 | N15: =COUNTIF('MA DATA'!$I$3:$I$136,'PETA-PENGAWAS'!K15) -> 4 | O15: =SUM(L15:N15) -> 12 | P15: 1
B16: GENDING | C16: =COUNTIF('RA DATA'!$J$3:$J$421,'PETA-PENGAWAS'!B16) -> 15 | E16: =COUNTIF('MI DATA'!$I$3:$I$417,'PETA-PENGAWAS'!B16) -> 12 | G16: =SUM(C16,E16) -> 27 | H16: 2 | K16: GENDING | L16: =COUNTIF('MTs DATA'!$I$3:$I$224,'PETA-PENGAWAS'!K16) -> 12 | N16: =COUNTIF('MA DATA'!$I$3:$I$136,'PETA-PENGAWAS'!K16) -> 7 | O16: =SUM(L16:N16) -> 19 | P16: 2
B17: DRINGU | C17: =COUNTIF('RA DATA'!$J$3:$J$421,'PETA-PENGAWAS'!B17) -> 2 | E17: =COUNTIF('MI DATA'!$I$3:$I$417,'PETA-PENGAWAS'!B17) -> 4 | G17: =SUM(C17,E17) -> 6 | H17: 1 | I17: Dari Gending | K17: DRINGU | L17: =COUNTIF('MTs DATA'!$I$3:$I$224,'PETA-PENGAWAS'!K17) -> 4 | N17: =COUNTIF('MA DATA'!$I$3:$I$136,'PETA-PENGAWAS'!K17) -> 2 | O17: =SUM(L17:N17) -> 6 | P17: 1
B18: LECES | C18: =COUNTIF('RA DATA'!$J$3:$J$421,'PETA-PENGAWAS'!B18) -> 19 | E18: =COUNTIF('MI DATA'!$I$3:$I$417,'PETA-PENGAWAS'!B18) -> 17 | G18: =SUM(C18,E18) -> 36 | H18: 3 | K18: LECES | L18: =COUNTIF('MTs DATA'!$I$3:$I$224,'PETA-PENGAWAS'!K18) -> 14 | N18: =COUNTIF('MA DATA'!$I$3:$I$136,'PETA-PENGAWAS'!K18) -> 7 | O18: =SUM(L18:N18) -> 21 | P18: 2
B19: TEGALSIWALAN | C19: =COUNTIF('RA DATA'!$J$3:$J$421,'PETA-PENGAWAS'!B19) -> 11 | E19: =COUNTIF('MI DATA'!$I$3:$I$417,'PETA-PENGAWAS'!B19) -> 13 | G19: =SUM(C19,E19) -> 24 | H19: 2 | K19: TEGALSIWALAN | L19: =COUNTIF('MTs DATA'!$I$3:$I$224,'PETA-PENGAWAS'!K19) -> 9 | N19: =COUNTIF('MA DATA'!$I$3:$I$136,'PETA-PENGAWAS'!K19) -> 6 | O19: =SUM(L19:N19) -> 15 | P19: 1
B20: BANYUANYAR | C20: =COUNTIF('RA DATA'!$J$3:$J$421,'PETA-PENGAWAS'!B20) -> 31 | E20: =COUNTIF('MI DATA'!$I$3:$I$417,'PETA-PENGAWAS'!B20) -> 29 | G20: =SUM(C20,E20) -> 60 | H20: 4 | K20: BANYUANYAR | L20: =COUNTIF('MTs DATA'!$I$3:$I$224,'PETA-PENGAWAS'!K20) -> 11 | N20: =COUNTIF('MA DATA'!$I$3:$I$136,'PETA-PENGAWAS'!K20) -> 8 | O20: =SUM(L20:N20) -> 19 | P20: 2
B21: MARON | C21: =COUNTIF('RA DATA'!$J$3:$J$421,'PETA-PENGAWAS'!B21) -> 27 | E21: =COUNTIF('MI DATA'!$I$3:$I$417,'PETA-PENGAWAS'!B21) -> 25 | G21: =SUM(C21,E21) -> 52 | H21: 4 | K21: MARON | L21: =COUNTIF('MTs DATA'!$I$3:$I$224,'PETA-PENGAWAS'!K21) -> 13 | N21: =COUNTIF('MA DATA'!$I$3:$I$136,'PETA-PENGAWAS'!K21) -> 8 | O21: =SUM(L21:N21) -> 21 | P21: 2
B22: GADING | C22: =COUNTIF('RA DATA'!$J$3:$J$421,'PETA-PENGAWAS'!B22) -> 34 | E22: =COUNTIF('MI DATA'!$I$3:$I$417,'PETA-PENGAWAS'!B22) -> 34 | G22: =SUM(C22,E22) -> 68 | H22: 4 | K22: GADING | L22: =COUNTIF('MTs DATA'!$I$3:$I$224,'PETA-PENGAWAS'!K22) -> 15 | N22: =COUNTIF('MA DATA'!$I$3:$I$136,'PETA-PENGAWAS'!K22) -> 7 | O22: =SUM(L22:N22) -> 22 | P22: 1
B23: TIRIS | C23: =COUNTIF('RA DATA'!$J$3:$J$421,'PETA-PENGAWAS'!B23) -> 0 | E23: =COUNTIF('MI DATA'!$I$3:$I$417,'PETA-PENGAWAS'!B23) -> 0 | G23: =SUM(C23,E23) -> 0 | K23: TIRIS | L23: =COUNTIF('MTs DATA'!$I$3:$I$224,'PETA-PENGAWAS'!K23) -> 17 | N23: =COUNTIF('MA DATA'!$I$3:$I$136,'PETA-PENGAWAS'!K23) -> 9 | O23: =SUM(L23:N23) -> 26 | P23: 1
B24: TIRIS BARAT | C24: =COUNTIF('RA DATA'!$J$3:$J$421,'PETA-PENGAWAS'!B24) -> 24 | E24: =COUNTIF('MI DATA'!$I$3:$I$417,'PETA-PENGAWAS'!B24) -> 26 | G24: =SUM(C24,E24) -> 50 | H24: 3 | K24: TIRIS BARAT | L24: =COUNTIF('MTs DATA'!$I$3:$I$224,'PETA-PENGAWAS'!K24) -> 0 | N24: =COUNTIF('MA DATA'!$I$3:$I$136,'PETA-PENGAWAS'!K24) -> 0 | O24: =SUM(L24:N24) -> 0
B25: TIRIS TIMUR | C25: =COUNTIF('RA DATA'!$J$3:$J$421,'PETA-PENGAWAS'!B25) -> 16 | E25: =COUNTIF('MI DATA'!$I$3:$I$417,'PETA-PENGAWAS'!B25) -> 25 | G25: =SUM(C25,E25) -> 41 | H25: 3 | K25: TIRIS TIMUR | L25: =COUNTIF('MTs DATA'!$I$3:$I$224,'PETA-PENGAWAS'!K25) -> 0 | N25: =COUNTIF('MA DATA'!$I$3:$I$136,'PETA-PENGAWAS'!K25) -> 0 | O25: =SUM(L25:N25) -> 0
B26: KRUCIL | C26: =COUNTIF('RA DATA'!$J$3:$J$421,'PETA-PENGAWAS'!B26) -> 35 | E26: =COUNTIF('MI DATA'!$I$3:$I$417,'PETA-PENGAWAS'!B26) -> 35 | G26: =SUM(C26,E26) -> 70 | H26: 4 | K26: KRUCIL | L26: =COUNTIF('MTs DATA'!$I$3:$I$224,'PETA-PENGAWAS'!K26) -> 17 | N26: =COUNTIF('MA DATA'!$I$3:$I$136,'PETA-PENGAWAS'!K26) -> 10 | O26: =SUM(L26:N26) -> 27 | P26: 1
B27: PAJARAKAN | C27: =COUNTIF('RA DATA'!$J$3:$J$421,'PETA-PENGAWAS'!B27) -> 9 | E27: =COUNTIF('MI DATA'!$I$3:$I$417,'PETA-PENGAWAS'!B27) -> 10 | G27: =SUM(C27,E27) -> 19 | H27: 1 | K27: PAJARAKAN | L27: =COUNTIF('MTs DATA'!$I$3:$I$224,'PETA-PENGAWAS'!K27) -> 6 | N27: =COUNTIF('MA DATA'!$I$3:$I$136,'PETA-PENGAWAS'!K27) -> 6 | O27: =SUM(L27:N27) -> 12 | P27: 1
B28: KREJENGAN | C28: =COUNTIF('RA DATA'!$J$3:$J$421,'PETA-PENGAWAS'!B28) -> 27 | E28: =COUNTIF('MI DATA'!$I$3:$I$417,'PETA-PENGAWAS'!B28) -> 26 | G28: =SUM(C28,E28) -> 53 | H28: 4 | K28: KREJENGAN | L28: =COUNTIF('MTs DATA'!$I$3:$I$224,'PETA-PENGAWAS'!K28) -> 12 | N28: =COUNTIF('MA DATA'!$I$3:$I$136,'PETA-PENGAWAS'!K28) -> 10 | O28: =SUM(L28:N28) -> 22 | P28: 1
B29: KRAKSAAN | C29: =COUNTIF('RA DATA'!$J$3:$J$421,'PETA-PENGAWAS'!B29) -> 20 | E29: =COUNTIF('MI DATA'!$I$3:$I$417,'PETA-PENGAWAS'!B29) -> 17 | G29: =SUM(C29,E29) -> 37 | H29: 3 | K29: KRAKSAAN | L29: =COUNTIF('MTs DATA'!$I$3:$I$224,'PETA-PENGAWAS'!K29) -> 14 | N29: =COUNTIF('MA DATA'!$I$3:$I$136,'PETA-PENGAWAS'!K29) -> 11 | O29: =SUM(L29:N29) -> 25 | P29: 2
B30: BESUK | C30: =COUNTIF('RA DATA'!$J$3:$J$421,'PETA-PENGAWAS'!B30) -> 16 | E30: =COUNTIF('MI DATA'!$I$3:$I$417,'PETA-PENGAWAS'!B30) -> 16 | G30: =SUM(C30,E30) -> 32 | H30: 3 | K30: BESUK | L30: =COUNTIF('MTs DATA'!$I$3:$I$224,'PETA-PENGAWAS'!K30) -> 4 | N30: =COUNTIF('MA DATA'!$I$3:$I$136,'PETA-PENGAWAS'!K30) -> 3 | O30: =SUM(L30:N30) -> 7 | P30: 1
B31: KOTAANYAR | C31: =COUNTIF('RA DATA'!$J$3:$J$421,'PETA-PENGAWAS'!B31) -> 15 | E31: =COUNTIF('MI DATA'!$I$3:$I$417,'PETA-PENGAWAS'!B31) -> 14 | G31: =SUM(C31,E31) -> 29 | H31: 2 | K31: KOTAANYAR | L31: =COUNTIF('MTs DATA'!$I$3:$I$224,'PETA-PENGAWAS'!K31) -> 6 | N31: =COUNTIF('MA DATA'!$I$3:$I$136,'PETA-PENGAWAS'!K31) -> 4 | O31: =SUM(L31:N31) -> 10 | P31: 1
B32: PAKUNIRAN | C32: =COUNTIF('RA DATA'!$J$3:$J$421,'PETA-PENGAWAS'!B32) -> 25 | E32: =COUNTIF('MI DATA'!$I$3:$I$417,'PETA-PENGAWAS'!B32) -> 25 | G32: =SUM(C32,E32) -> 50 | H32: 4 | K32: PAKUNIRAN | L32: =COUNTIF('MTs DATA'!$I$3:$I$224,'PETA-PENGAWAS'!K32) -> 12 | N32: =COUNTIF('MA DATA'!$I$3:$I$136,'PETA-PENGAWAS'!K32) -> 5 | O32: =SUM(L32:N32) -> 17
B33: PAITON | C33: =COUNTIF('RA DATA'!$J$3:$J$421,'PETA-PENGAWAS'!B33) -> 19 | E33: =COUNTIF('MI DATA'!$I$3:$I$417,'PETA-PENGAWAS'!B33) -> 23 | G33: =SUM(C33,E33) -> 42 | H33: 4 | K33: PAITON | L33: =COUNTIF('MTs DATA'!$I$3:$I$224,'PETA-PENGAWAS'!K33) -> 17 | N33: =COUNTIF('MA DATA'!$I$3:$I$136,'PETA-PENGAWAS'!K33) -> 11 | O33: =SUM(L33:N33) -> 28 | P33: 1
C34: =SUM($C$8:$C$33) -> 419 | D34: =SUM(D8:D33) -> 0 | E34: =SUM($E$8:$E$33) -> 415 | F34: =SUM(F8:F33) -> 0 | G34: =SUM($G$8:$G$33) -> 834 | H34: =SUM(H8:H33) -> 59 | I34: =SUM(I8:I33) -> 0 | L34: =SUM($L$8:$L$33) -> 222 | M34: =SUM(M8:M33) -> 0 | N34: =SUM($N$8:$N$33) -> 133 | O34: =SUM($O$8:$O$33) -> 355 | P34: =SUM(P8:P33) -> 24

Sheet PETA_WAS_RA-MI
B1: DESKRIPSI PEMBAGIAN KUOTA PENGAWAS DAN WILAYAH BINAAN 2025 | K1: PEMBAGIAN KUOTA PENGAWAS RA-MI DAN WILAYAH BINAAN 2025
B2: JUMLAH PENGAWAS RA/MI | G2: ='PETA-PENGAWAS'!G4 -> 58
B4: KECAMATAN/KKM | C4: JUMLAH | H4: QUOTA PENGAWAS | I4: LEMBAGA TAMBAHAN | J4: NO | K4: NAMA PENGAWAS | L4: JENIS KELAMIN | M4: TMT PENSIUN | N4: WILAYAH LAMA | O4: TMT SP WILAYAH LAMA | P4: WILAYAH BARU | Q4: ALAMAT RUMAH
C5: RA | D5: QUATA PENGAWAS | E5: MI | F5: QUATA PENGAWAS | G5: RA/MI
B6: SUMBER | C6: =COUNTIF('RA DATA'!$J$3:$J$421,'PETA_WAS_RA-MI'!B6) -> 1 | E6: =COUNTIF('MI DATA'!$I$3:$I$417,'PETA_WAS_RA-MI'!B6) -> 0 | G6: =SUM(C6,E6) -> 1 | H6: ='PETA-PENGAWAS'!H8 -> 1 | I6: Wonomerto | J6: =IF(K6="","",1) -> 1 | K6: M. MUSHLIH | L6: =IFERROR(IF(K6="","",VLOOKUP(K6,CHOOSE({1,2},'Data Pengawas RA-MI'!$Q$5:$Q$62,'Data Pengawas RA-MI'!$D$5:$D$62),2,0)),"") -> L | M6: =IF(K6="","",VLOOKUP(K6,CHOOSE({1,2},'Data Pengawas RA-MI'!$Q$5:$Q$62,'Data Pengawas RA-MI'!$N$5:$N$62),2,0)) -> 17 Juli 2031 | N6: =IF(K6="","",VLOOKUP(K6,CHOOSE({1,2},'Data Pengawas RA-MI'!$Q$5:$Q$62,'Data Pengawas RA-MI'!$I$5:$I$62),2,0)) -> Pengawas RA,MI Kec. Lumbang, Sukapura | O6: =TEXT(IF(K6="","",VLOOKUP(K6,CHOOSE({1,2},'Data Pengawas RA-MI'!$Q$5:$Q$62,'Data Pengawas RA-MI'!$G$5:$G$62),2,0)),"DD MMMM YYYY") -> 01 April 2022 | P6: =IF(K6="","",W6) -> Pengawas RA,MI Sumber, Sukapura dan Lumbang | Q6: =IF(K6="","",VLOOKUP(K6,CHOOSE({1,2},'Data Pengawas RA-MI'!$Q$5:$Q$62,'Data Pengawas RA-MI'!$P$5:$P$62),2,0)) -> Wonomerto | U6: Sumber, Sukapura dan Lumbang | W6: ="Pengawas RA,MI "&U6 -> Pengawas RA,MI Sumber, Sukapura dan Lumbang
B7: SUKAPURA | C7: =COUNTIF('RA DATA'!$J$3:$J$421,'PETA_WAS_RA-MI'!B7) -> 2 | E7: =COUNTIF('MI DATA'!$I$3:$I$417,'PETA_WAS_RA-MI'!B7) -> 0 | G7: =SUM(C7,E7) -> 2
B8: LUMBANG | C8: =COUNTIF('RA DATA'!$J$3:$J$421,'PETA_WAS_RA-MI'!B8) -> 7 | E8: =COUNTIF('MI DATA'!$I$3:$I$417,'PETA_WAS_RA-MI'!B8) -> 6 | G8: =SUM(C8,E8) -> 13
B9: WONOMERTO | C9: =COUNTIF('RA DATA'!$J$3:$J$421,'PETA_WAS_RA-MI'!B9) -> 7 | E9: =COUNTIF('MI DATA'!$I$3:$I$417,'PETA_WAS_RA-MI'!B9) -> 11 | G9: =SUM(C9,E9) -> 18 | H9: ='PETA-PENGAWAS'!H12 -> 1 | J9: =IF(K9="","",J11+1) -> 4 | K9: SUBIHASTUTIK | L9: =IFERROR(IF(K9="","",VLOOKUP(K9,CHOOSE({1,2},'Data Pengawas RA-MI'!$Q$5:$Q$62,'Data Pengawas RA-MI'!$D$5:$D$62),2,0)),"") -> P | M9: =IFERROR(IF(K9="","",VLOOKUP(K9,CHOOSE({1,2},'Data Pengawas RA-MI'!$Q$5:$Q$62,'Data Pengawas RA-MI'!$N$5:$N$62),2,0)),"") -> 10 Maret 2030 | N9: =IFERROR(IF(K9="","",VLOOKUP(K9,CHOOSE({1,2},'Data Pengawas RA-MI'!$Q$5:$Q$62,'Data Pengawas RA-MI'!$I$5:$I$62),2,0)),"") -> Pengawas RA,MI Kec. Onomerto | O9: =IFERROR(TEXT(IF(K9="","",VLOOKUP(K9,CHOOSE({1,2},'Data Pengawas RA-MI'!$Q$5:$Q$62,'Data Pengawas RA-MI'!$G$5:$G$62),2,0)),"DD MMMM YYYY"),"") -> 01 Juli 2024 | P9: =IFERROR(IF(K9="x","",W9),"") -> Pengawas RA,MI Kec. Wonomerto | Q9: =IFERROR(IF(K9="","",VLOOKUP(K9,CHOOSE({1,2},'Data Pengawas RA-MI'!$Q$5:$Q$62,'Data Pengawas RA-MI'!$P$5:$P$62),2,0)),"") -> Kanigaran | U9: Wonomerto | W9: ="Pengawas RA,MI Kec. "&U9 -> Pengawas RA,MI Kec. Wonomerto
